<?xml version="1.0"?>
<robot name="Minotaur" xmlns:xacro="http://ros.org/wiki/xacro">

  <xacro:property name="width" value="0.44" />
  <xacro:property name="length" value="0.75" />
  <xacro:property name="height" value="0.2" />
  <xacro:property name="mastheight" value="0.74" />
  <xacro:property name="mastside" value="0.05" />
  <xacro:property name="wheelrad" value="0.16" />
  <xacro:property name="pi" value="3.1415" />
  <xacro:property name="clearance" value="0.15" />

	<material name="blue">
		<color rgba="0 0 0.8 1"/>
	</material>
	
	<material name="black">
		<color rgba="0 0 0 1"/>
	</material>
	
	<material name="white">
		<color rgba="1 1 1 1"/>
	</material>
	
	<link name="base_link">
		<visual>
			<geometry>
				<box size="${width} ${length} ${height}"/>
			</geometry>
			<material name="blue"/>
		</visual>
		<collision>
			<geometry>
				<box size="${width} ${length} ${height}"/>
			</geometry>
		</collision>
		<inertial>
      <mass value="10"/>
      <inertia ixx="0.5" ixy="0.0" ixz="0.0" iyy="0.2" iyz="0.0" izz="0.63"/>
    </inertial>
	</link>
	
	<link name="front_end">
		<visual>
			<geometry>
				<cylinder length="${height}" radius="${width/2}"/>
			</geometry>
			<material name="blue"/>
			<origin xyz="0 0 0"/>
		</visual>
		<collision>
			<geometry>
				<cylinder length="${height}" radius="${width/2}"/>
			</geometry>
		</collision>
		<inertial>
      <mass value="5"/>
      <inertia ixx="0.1" ixy="0.0" ixz="0.0" iyy="0.1" iyz="0.0" izz="0.1"/>
    </inertial>
	</link>
	
	<joint name="front_base_joint" type="fixed">
		<parent link="base_link"/>
		<child link="front_end"/>
		<origin xyz="0 0.375 0"/>
	</joint>
	
	<link name="right_wheel">
		<visual>
			<origin rpy="0 ${pi/2} 0" xyz="0 0 0"/>
			<geometry>
				<cylinder length="${wheelrad/2}" radius="${wheelrad}"/>
			</geometry>
			<material name="black"/>
		</visual>
		<collision>
			<geometry>
				<cylinder length="${wheelrad/2}" radius="${wheelrad}"/>
			</geometry>
		</collision>
		<inertial>
      <mass value="1"/>
      <inertia ixx="0.007" ixy="0.0" ixz="0.0" iyy="0.007" iyz="0.0" izz="0.01"/>
    </inertial>
	</link>
		
	<joint name="right_wheel_joint" type="continuous">
		<parent link="base_link"/>
		<child link="right_wheel"/>
		<origin xyz="0.26 0.1 -0.09" rpy="${pi/2} 0 0"/>
	</joint>
	
	<link name="left_wheel">
		<visual>
			<origin rpy="0 ${pi/2} 0" xyz="0 0 0"/>
			<geometry>
				<cylinder length="${wheelrad/2}" radius="${wheelrad}"/>
			</geometry>
			<material name="black"/>
		</visual>
		<collision>
			<geometry>
				<cylinder length="${wheelrad/2}" radius="${wheelrad}"/>
			</geometry>
		</collision>
		<inertial>
      <mass value="1"/>
      <inertia ixx="0.007" ixy="0.0" ixz="0.0" iyy="0.007" iyz="0.0" izz="0.01"/>
    </inertial>
	</link>
		
	<joint name="left_wheel_joint" type="continuous">
		<parent link="base_link"/>
		<child link="left_wheel"/>
		<origin xyz="-0.26 0.1 -0.09" rpy="${pi/2} 0 0"/>
	</joint>
	
	<link name="right_mast">
		<visual>
			<geometry>
				<box size="${mastside} ${mastside} ${mastheight}"/>
			</geometry>
			<material name="white"/>
		</visual>
		<collision>
			<geometry>
				<box size="${mastside} ${mastside} ${mastheight}"/>
			</geometry>
		</collision>
		<inertial>
      <mass value="2"/>
      <inertia ixx="0.1" ixy="0.0" ixz="0.0" iyy="0.1" iyz="0.0" izz="0.001"/>
    </inertial>
	</link>
	
	<link name="left_mast">
		<visual>
			<geometry>
				<box size="${mastside} ${mastside} ${mastheight}"/>
			</geometry>
			<material name="white"/>
		</visual>
		<collision>
			<geometry>
				<box size="${mastside} ${mastside} ${mastheight}"/>
			</geometry>
		</collision>
		<inertial>
      <mass value="2"/>
      <inertia ixx="0.1" ixy="0.0" ixz="0.0" iyy="0.1" iyz="0.0" izz="0.001"/>
    </inertial>
	</link>
	
	<joint name="right_mast_joint" type="fixed">
		<parent link="base_link"/>
		<child link="right_mast"/>
		<origin xyz="0.195 0.1 0.47"/>
	</joint>
	
	<joint name="left_mast_joint" type="fixed">
		<parent link="base_link"/>
		<child link="left_mast"/>
		<origin xyz="-0.195 0.1 0.47"/>
	</joint>	
	
	<link name="mast_link">
		<visual>
			<geometry>
				<box size="0.34 ${mastside} ${mastside}"/>
			</geometry>
			<material name="white"/>
		</visual>
		<collision>
			<geometry>
				<box size="0.34 ${mastside} ${mastside}"/>
			</geometry>
		</collision>
		<inertial>
      <mass value="1"/>
      <inertia ixx="0.01" ixy="0.0" ixz="0.0" iyy="0.002" iyz="0.0" izz="0.01"/>
    </inertial>
	</link>
	
	<joint name="left_cam_joint" type="fixed">
		<parent link="left_mast"/>
		<child link="mast_link"/>
		<origin xyz="0.195 0 0.25"/>
	</joint>
		
	<joint name="right_cam_joint" type="fixed">
		<parent link="right_mast"/>
		<child link="mast_link"/>
		<origin xyz="-0.195 0 0.25"/>
	</joint>
	
	<link name="caster_wheel">
		<visual>
			<origin rpy="0 ${pi/2} 0" xyz="0 0 0"/>
			<geometry>
				<cylinder length="0.1" radius="0.075"/>
			</geometry>
			<material name="white"/>
		</visual>
		<collision>
			<geometry>
				<cylinder length="0.1" radius="0.075"/>
			</geometry>
		</collision>
		<inertial>
      <mass value="1"/>
      <inertia ixx="0.01" ixy="0.0" ixz="0.0" iyy="0.01" iyz="0.0" izz="0.01"/>
    </inertial>
	</link>
	
	<joint name="caster_joint" type="continuous">
		<parent link="base_link"/>
		<child link="caster_wheel"/>
		<origin xyz="0 -0.35 -0.175" rpy="${pi/2} 0 0"/>
	</joint>
	
	<!-- Gazebo plugin for ROS Control -->
  <gazebo>
    <plugin name="gazebo_ros_control" filename="libgazebo_ros_control.so">
      <robotNamespace>/</robotNamespace>
    </plugin>
  </gazebo>

</robot>
